<?xml version="1.0"?>
<robot xmlns:xacro="http://www.ros.org/wiki/xacro">
  <xacro:macro name="za_macro" params="prefix tool0_trans tool0_rot tool0_fixed">

    <material name="${prefix}TormachBlue">
      <color rgba="0.1490 0.2196 0.2667 0.99"/>
    </material>
    <material name="${prefix}Black">
      <color rgba="0.0 0.0 0.0 0.99"/>
    </material>

    <!-- link list -->
    <link name="${prefix}base_link">
      <visual>
        <geometry>
          <mesh filename="package://za_description/meshes/base_link.stl"/>
        </geometry>
        <origin rpy="0.0 0 0.0" xyz="0 0 0"/>
        <material name="${prefix}TormachBlue">
        </material>
      </visual>
      <collision>
        <geometry>
          <mesh filename="package://za_description/meshes/base_link_collision.stl"/>
        </geometry>
        <origin rpy="0.0 0 0.0" xyz="0 0 0"/>
      </collision>
    </link>
    <link name="${prefix}link_1">
      <visual>
        <geometry>
          <mesh filename="package://za_description/meshes/link_1.stl"/>
        </geometry>
        <origin rpy="0.0 0 0.0" xyz="0 0 0"/>
        <material name="${prefix}TormachBlue">
        </material>
      </visual>
      <collision>
        <geometry>
          <mesh filename="package://za_description/meshes/link_1_collision.stl"/>
        </geometry>
        <origin rpy="0.0 0 0.0" xyz="0 0 0"/>
      </collision>
      <inertial>
        <mass value="100"/>
        <inertia ixx="1.0" ixy="0.0" ixz="0.0" iyy="1.0" iyz="0.0" izz="1.0"/>
      </inertial>
    </link>

    <link name="${prefix}link_2">
      <visual>
        <geometry>
          <mesh filename="package://za_description/meshes/link_2.stl"/>
        </geometry>
        <origin rpy="0.0 0 0.0" xyz="0 0 0"/>
        <material name="${prefix}TormachBlue">
        </material>
      </visual>
      <collision>
        <geometry>
          <mesh filename="package://za_description/meshes/link_2_collision.stl"/>
        </geometry>
        <origin rpy="0.0 0 0.0" xyz="0 0 0"/>
      </collision>
      <inertial>
        <mass value="100"/>
        <inertia ixx="1.0" ixy="0.0" ixz="0.0" iyy="1.0" iyz="0.0" izz="1.0"/>
      </inertial>
    </link>

    <link name="${prefix}link_3">
      <visual>
        <geometry>
          <mesh filename="package://za_description/meshes/link_3.stl"/>
        </geometry>
        <origin rpy="0.0 0 0.0" xyz="0 0 0"/>
        <material name="${prefix}TormachBlue">
        </material>
      </visual>
      <collision>
        <geometry>
          <mesh filename="package://za_description/meshes/link_3_collision.stl"/>
        </geometry>
        <origin rpy="0.0 0 0.0" xyz="-0 0 0"/>
      </collision>
      <inertial>
        <mass value="100"/>
        <inertia ixx="1.0" ixy="0.0" ixz="0.0" iyy="1.0" iyz="0.0" izz="1.0"/>
      </inertial>
    </link>


    <link name="${prefix}link_4">
      <visual>
        <geometry>
          <mesh filename="package://za_description/meshes/link_4.stl"/>
        </geometry>
        <origin rpy="0.0 0.0 0.0" xyz="0 0 0"/>
        <material name="${prefix}TormachBlue">
        </material>
      </visual>
      <collision>
        <geometry>
          <mesh filename="package://za_description/meshes/link_4_collision.stl"/>
        </geometry>
        <origin rpy="0.0 0 0.0" xyz="0 0 0"/>
      </collision>
      <inertial>
        <mass value="100"/>
        <inertia ixx="1.0" ixy="0.0" ixz="0.0" iyy="1.0" iyz="0.0" izz="1.0"/>
      </inertial>
    </link>

    <link name="${prefix}link_5">
      <visual>
        <geometry>
          <mesh filename="package://za_description/meshes/link_5.stl"/>
        </geometry>
        <origin rpy="0 0 0" xyz="0 0 0"/>
        <material name="${prefix}TormachBlue">
        </material>
      </visual>
      <collision>
        <geometry>
          <mesh filename="package://za_description/meshes/link_5_collision.stl"/>
        </geometry>
        <origin rpy="0 0 0" xyz="0 0 0"/>
      </collision>
      <inertial>
        <mass value="100"/>
        <inertia ixx="1.0" ixy="0.0" ixz="0.0" iyy="1.0" iyz="0.0" izz="1.0"/>
      </inertial>
    </link>

    <link name="${prefix}link_6">
      <visual>
        <geometry>
          <mesh filename="package://za_description/meshes/link_6.stl"/>
        </geometry>
        <origin rpy="0 0 0.0" xyz="0 0 0"/>
        <material name="Black">
        </material>
      </visual>
      <collision>
        <geometry>
          <mesh filename="package://za_description/meshes/link_6_collision.stl"/>
        </geometry>
        <origin rpy="0 0 0.0" xyz="0 0 0"/>
      </collision>
      <inertial>
        <mass value="100"/>
        <inertia ixx="1.0" ixy="0.0" ixz="0.0" iyy="1.0" iyz="0.0" izz="1.0"/>
      </inertial>
    </link>

    <!-- joint list -->
    <joint name="${prefix}joint_1" type="revolute">
      <limit effort="1000.0" lower="-2.96" upper="2.96" velocity="2.6"/>
      <parent link="${prefix}base_link"/>
      <child link="${prefix}link_1"/>
      <axis xyz="0 0 1"/>
      <origin rpy="0.0 0.0 0.0" xyz="0 0 0.279"/>
    </joint>

    <joint name="${prefix}joint_2" type="revolute">
      <limit effort="1000.0" lower="-1.74" upper="2.35" velocity="1.9"/>
      <parent link="${prefix}link_1"/>
      <child link="${prefix}link_2"/>
      <axis xyz="0 1 0"/>
      <origin rpy="0.0 0.0 0.0" xyz="0.025 0 0.171"/>
    </joint>

    <xacro:arg name="mastering" default="false"/>
    <xacro:property name="mastering" value="$(arg mastering)"/>
    <xacro:property name="j3_lower_limit" value="${-3.7 if mastering else -pi / 2.}"/>
    <xacro:property name="j6_limit" value="${2*pi if mastering else pi}"/>

    <joint name="${prefix}joint_3" type="revolute">
      <limit effort="1000.0" lower="${j3_lower_limit}" upper="1.15" velocity="2.6"/>
      <parent link="${prefix}link_2"/>
      <child link="${prefix}link_3"/>
      <axis xyz="0 1 0"/>
      <origin rpy="0.0 ${pi/2.0} 0.0" xyz="0.0 -0.001 0.454"/>
    </joint>

    <joint name="${prefix}joint_4" type="revolute">
      <limit effort="1000.0" lower="-2.6" upper="2.6" velocity="3.5"/>
      <parent link="${prefix}link_3"/>
      <child link="${prefix}link_4"/>
      <axis xyz="0 0 1"/>
      <origin rpy="0.0 0.0 0.0" xyz="-0.035 -0 0.123"/>
    </joint>
    <joint name="${prefix}joint_5" type="revolute">
      <limit effort="1000.0" lower="-2.49" upper="2.49" velocity="3.9"/>
      <parent link="${prefix}link_4"/>
      <child link="${prefix}link_5"/>
      <axis xyz="0 1 0"/>
      <origin rpy="0.0 0.0 0.0" xyz="0.0 0.001 0.2965"/>
    </joint>

    <joint name="${prefix}joint_6" type="revolute">
      <limit effort="1000.0" lower="${-j6_limit}" upper="${j6_limit}" velocity="${pi*2}"/>
      <parent link="${prefix}link_5"/>
      <child link="${prefix}link_6"/>
      <axis xyz="0 0 1"/>
      <origin rpy="0.0 0.0 0.0" xyz="0 0 0.1"/>
    </joint>


    <!-- ROS-Industrial 'base' frame: base_link to Fanuc World Coordinates transform -->
    <link name="${prefix}base" />
    <joint name="${prefix}base_link-base" type="fixed">
      <origin xyz="0 0 0" rpy="0 0 0"/>
      <axis xyz="0 0 1"/>
      <parent link="${prefix}base_link"/>
      <child link="${prefix}base"/>
    </joint>

    <!-- ROS-Industrial 'flange' frame: attachment point for EEF models -->
    <link name="${prefix}flange" />
    <joint name="${prefix}joint_6-flange" type="fixed">
      <origin xyz="0 0 0" rpy="0 0 0" />
      <parent link="${prefix}link_6" />
      <child link="${prefix}flange" />
    </joint>

    <!-- ROS-Industrial 'tool0' frame: all-zeros tool frame -->
    <link name="${prefix}tool0" />
    <xacro:if value="${tool0_fixed}">
      <joint name="${prefix}link_6_tool0" type="fixed">
        <!-- marker -->
        <origin xyz="${tool0_trans}" rpy="${tool0_rot}" />
        <parent link="${prefix}link_6" />
        <child link="${prefix}tool0" />
      </joint>
    </xacro:if>
    <xacro:unless value="${tool0_fixed}">
      <joint name="${prefix}link_6_tool0" type="floating">
        <origin xyz="0 0 0" rpy="0 0 0" />
        <parent link="${prefix}link_6" />
        <child link="${prefix}tool0" />
      </joint>
    </xacro:unless>

  </xacro:macro>
</robot>
